Workbook

Sheet PICOC & RQs
A1: PICOC Element | B1: Description
A2: Problem | B2: Studies proposing or evaluating hybrid ANN–SNN or pure SNN architectures for neuromorphic or event-driven learning tasks, where spike encoding plays a functional role in the learning pipeline.
A3: Intervention | B3: Introduction or application of learnable and/or adaptive spike-encoding mechanisms (e.g., gradient-trained or plasticity-based) for temporal and/or spatial information conversion.
A4: Comparison | B4: Conventional or rule-based spike encoders (e.g., rate, latency, phase coding) used in hybrid or pure SNNs.
A5: Outcome | B5: Quantitative results for model performance (e.g., accuracy), computational efficiency (e.g., energy, spike count), training stability, and/or biological plausibility.
A6: Context | B6: Empirical studies conducted using standard neuromorphic datasets (e.g., DVS Gesture, N-MNIST, SHD) and evaluated under both software simulation environments and neuromorphic hardware platforms.
A8: RQs
A9: Purpose | B9: Question Stem
A10: To systematically catalog and characterize the landscape of existing learnable encoding methods, providing a comprehensive taxonomy of approaches and their technical implementations. | B10: RQ1. Findings for RQ1: What learnable or adaptive spike-encoding mechanisms have been proposed in pure SNN or hybrid ANN--SNN architectures?
A11: To quantitatively assess the empirical benefits and trade-offs of learnable encoding methods, determining whether they provide meaningful improvements over traditional approaches. | B11: RQ2. How have these mechanisms influenced model performance, computational efficiency, and training behavior compared with traditional fixed encoding methods?
A12: To identify standardization practices and methodological consistencies (or lack thereof) in the field, revealing community norms and evaluation gaps. | B12: RQ3. What datasets, benchmarks, and evaluation metrics are most commonly used in existing studies?
A13: To synthesize critical challenges and identify promising future research directions that could advance both theoretical understanding and practical applications. | B13: RQ4. What limitations and research gaps remain in developing biologically plausible and energy-efficient encoding strategies?

Sheet search terms
A1: PICOC | B1: Key term | C1: Synonyms / Related Terms
A2: P | B2: Spiking neural network* | C2: "Spiking neural network*" OR "SNN" OR "neuromorphic network*" OR "deep spiking network*" OR "pulsed neural network*" OR "event-driven neural network" OR "event-based spiking network"
A3: P | B3: Hybrid ANN-SNN | C3: "Hybrid ANN-SNN" OR "ANN-SNN conversion" OR "hybrid neural network*" OR "hybrid spiking network*" OR "artificial and spiking neural network*"
A4: I | B4: Learnable encoding | C4: "Learnable encoding" OR "Adaptive encoding" OR "learnable spike encoding" OR "adaptive spike encoding" OR "trainable encoder" OR "differentiable encoding" OR "plastic encoding" OR "adaptive threshold encoding" OR "learnable threshold" OR "surrogate gradient"
A5: I | B5: Adaptive encoding | C5: "Learnable encoding" OR "Adaptive encoding" OR "learnable spike encoding" OR "adaptive spike encoding" OR "trainable encoder" OR "differentiable encoding" OR "plastic encoding" OR "adaptive threshold encoding" OR "learnable threshold" OR "surrogate gradient"
A6: C | B6: Traditional encoding | C6: "TTFS" OR "time-to-first-spike" OR "static" OR "hand-crafted" OR "conventional" OR "rule-based" OR "traditional encoding" OR "rate" OR "temporal encoding" OR "population encoding" OR "direct encoding" OR "latency" OR "fixed threshold" OR "non-adaptive" OR "Poisson"
A7: Ctx | B7: Neuromorphic dataset* | C7: "event-based dataset*" OR "DVS Gesture" OR "N-MNIST" OR "SHD" OR "Spiking Heidelberg Digits" OR "CIFAR-10-DVS" OR "neuromorphic benchmark"
A8: Ctx | B8: Simulation framework* | C8: "software simulation" OR "neuromorphic hardware" OR "Loihi" OR "SpiNNaker" OR "TrueNorth" OR "BindsNET" OR "snnTorch" OR "neuromorphic simulator"

Sheet queries
A1: Query ID | B1: Purpose | C1: Core keywords | D1: Expanded | E1: #tokens
A2: Q1 | B2: To find studies on hybrid ANN–SNN models using learnable or adaptive spike-encoding mechanisms. | C2: "Spiking neural network*" AND "Hybrid ANN-SNN" AND ("Learnable encoding" OR "Adaptive encoding") | D2: ="(" & _xlfn.XLOOKUP("Spiking neural network*",'search terms'!B:B,'search terms'!C:C) & ") AND (" & _xlfn.XLOOKUP("Hybrid ANN-SNN",'search terms'!B:B,'search terms'!C:C) & ") AND (" & _xlfn.XLOOKUP("Learnable encoding",'search terms'!B:B,'search terms'!C:C) & ")" -> ("Spiking neural network*" OR "SNN" OR "neuromorphic network*" OR "deep spiking network*" OR "pulsed neural network*" OR "event-driven neural network" OR "event-based spiking network") AND ("Hybrid ANN-SNN" OR "ANN-SNN conversion" OR "hybrid neural network*" OR "hybrid spiking network*" OR "artificial and spiking neural network*") AND ( "Learnable encoding" OR "Adaptive encoding" OR "learnable spike encoding" OR "adaptive spike encoding" OR "trainable encoder" OR "differentiable encoding" OR "plastic encoding" OR "adaptive threshold encoding" OR "learnable threshold" OR "surrogate gradient") | E2: =ROWS(_xlfn.TEXTSPLIT(D2,," ")) -> 78
A3: Q2 | B3: To identify studies that investigate learnable or adaptive spike-encoding methods, evaluated on event-based or neuromorphic datasets, and compared against traditional encoding approaches. | C3: "Adaptive encoding" AND "Neuromorphic dataset*" AND "Traditional encoding" | D3: ="("&_xlfn.XLOOKUP("Adaptive encoding",'search terms'!B:B,'search terms'!C:C)&") AND ("&_xlfn.XLOOKUP("Neuromorphic dataset*",'search terms'!B:B,'search terms'!C:C) &") AND ("&_xlfn.XLOOKUP("Traditional encoding",'search terms'!B:B,'search terms'!C:C) & ")" -> ( "Learnable encoding" OR "Adaptive encoding" OR "learnable spike encoding" OR "adaptive spike encoding" OR "trainable encoder" OR "differentiable encoding" OR "plastic encoding" OR "adaptive threshold encoding" OR "learnable threshold" OR "surrogate gradient") AND ("event-based dataset*" OR "DVS Gesture" OR "N-MNIST" OR "SHD" OR "Spiking Heidelberg Digits" OR "CIFAR-10-DVS" OR "neuromorphic benchmark") AND ("TTFS" OR "time-to-first-spike" OR "static" OR "hand-crafted" OR "conventional" OR "rule-based" OR "traditional encoding" OR "rate" OR "temporal encoding" OR "population encoding" OR "direct encoding" OR "latency" OR "fixed threshold" OR "non-adaptive" OR "Poisson") | E3: =ROWS(_xlfn.TEXTSPLIT(D3,," ")) -> 87
A4: Q3 | B4: To identify studies that employ adaptive encoding methods on event-based datasets, implemented using neuromorphic hardware or simulation frameworks. | C4: "Neuromorphic dataset*" AND "Simulation framework*" AND "Adaptive encoding" | D4: ="(" & _xlfn.XLOOKUP("Neuromorphic dataset*",'search terms'!B:B,'search terms'!C:C) & ") AND (" & _xlfn.XLOOKUP("Simulation framework*",'search terms'!B:B,'search terms'!C:C) & ") AND (" & _xlfn.XLOOKUP("Adaptive encoding",'search terms'!B:B,'search terms'!C:C) & ")" -> ("event-based dataset*" OR "DVS Gesture" OR "N-MNIST" OR "SHD" OR "Spiking Heidelberg Digits" OR "CIFAR-10-DVS" OR "neuromorphic benchmark") AND ("software simulation" OR "neuromorphic hardware" OR "Loihi" OR "SpiNNaker" OR "TrueNorth" OR "BindsNET" OR "snnTorch" OR "neuromorphic simulator") AND ( "Learnable encoding" OR "Adaptive encoding" OR "learnable spike encoding" OR "adaptive spike encoding" OR "trainable encoder" OR "differentiable encoding" OR "plastic encoding" OR "adaptive threshold encoding" OR "learnable threshold" OR "surrogate gradient") | E4: =ROWS(_xlfn.TEXTSPLIT(D4,," ")) -> 71
A5: Q4 | B5: To identify studies on spiking or neuromorphic neural networks that employ learnable or adaptive spike-encoding techniques, implemented using neuromorphic hardware or simulation frameworks. | C5: ("Learnable encoding" OR "Adaptive encoding") AND "Spiking neural network*" AND "Simulation framework*" | D5: ="(" & _xlfn.XLOOKUP("Learnable encoding",'search terms'!B:B,'search terms'!C:C) & ") AND (" & _xlfn.XLOOKUP( "Spiking neural network*",'search terms'!B:B,'search terms'!C:C) &") AND (" & _xlfn.XLOOKUP( "Simulation framework*",'search terms'!B:B,'search terms'!C:C) &")" -> ( "Learnable encoding" OR "Adaptive encoding" OR "learnable spike encoding" OR "adaptive spike encoding" OR "trainable encoder" OR "differentiable encoding" OR "plastic encoding" OR "adaptive threshold encoding" OR "learnable threshold" OR "surrogate gradient") AND ("Spiking neural network*" OR "SNN" OR "neuromorphic network*" OR "deep spiking network*" OR "pulsed neural network*" OR "event-driven neural network" OR "event-based spiking network") AND ("software simulation" OR "neuromorphic hardware" OR "Loihi" OR "SpiNNaker" OR "TrueNorth" OR "BindsNET" OR "snnTorch" OR "neuromorphic simulator") | E5: =ROWS(_xlfn.TEXTSPLIT(D5,," ")) -> 77
A6: Q5 | B6: To find studies on hybrid ANN–SNN architectures evaluated using event-based or neuromorphic datasets, and compared against traditional encoding approaches. | C6: "Spiking neural network*" AND "Hybrid ANN-SNN" AND "Neuromorphic dataset*" AND "Traditional encoding" | D6: ="(" & _xlfn.XLOOKUP("Spiking neural network*",'search terms'!B:B,'search terms'!C:C) & ") AND (" & _xlfn.XLOOKUP("Hybrid ANN-SNN",'search terms'!B:B,'search terms'!C:C) & ") AND (" & _xlfn.XLOOKUP("Neuromorphic dataset*",'search terms'!B:B,'search terms'!C:C) & ") AND (" & _xlfn.XLOOKUP("Traditional encoding",'search terms'!B:B,'search terms'!C:C) & ")" -> ("Spiking neural network*" OR "SNN" OR "neuromorphic network*" OR "deep spiking network*" OR "pulsed neural network*" OR "event-driven neural network" OR "event-based spiking network") AND ("Hybrid ANN-SNN" OR "ANN-SNN conversion" OR "hybrid neural network*" OR "hybrid spiking network*" OR "artificial and spiking neural network*") AND ("event-based dataset*" OR "DVS Gesture" OR "N-MNIST" OR "SHD" OR "Spiking Heidelberg Digits" OR "CIFAR-10-DVS" OR "neuromorphic benchmark") AND ("TTFS" OR "time-to-first-spike" OR "static" OR "hand-crafted" OR "conventional" OR "rule-based" OR "traditional encoding" OR "rate" OR "temporal encoding" OR "population encoding" OR "direct encoding" OR "latency" OR "fixed threshold" OR "non-adaptive" OR "Poisson") | E6: =ROWS(_xlfn.TEXTSPLIT(D6,," ")) -> 98
A7: Q6 | B7: To locate studies on hybrid ANN–SNN models implemented or tested using neuromorphic hardware or simulation platforms. | C7: "Spiking neural network*" AND "Hybrid ANN-SNN" AND "Simulation framework*" | D7: ="(" & _xlfn.XLOOKUP("Spiking neural network*",'search terms'!B:B,'search terms'!C:C) & ") AND (" & _xlfn.XLOOKUP("Hybrid ANN-SNN",'search terms'!B:B,'search terms'!C:C) & ") AND (" & _xlfn.XLOOKUP("Simulation framework*",'search terms'!B:B,'search terms'!C:C) & ")" -> ("Spiking neural network*" OR "SNN" OR "neuromorphic network*" OR "deep spiking network*" OR "pulsed neural network*" OR "event-driven neural network" OR "event-based spiking network") AND ("Hybrid ANN-SNN" OR "ANN-SNN conversion" OR "hybrid neural network*" OR "hybrid spiking network*" OR "artificial and spiking neural network*") AND ("software simulation" OR "neuromorphic hardware" OR "Loihi" OR "SpiNNaker" OR "TrueNorth" OR "BindsNET" OR "snnTorch" OR "neuromorphic simulator") | E7: =ROWS(_xlfn.TEXTSPLIT(D7,," ")) -> 63
A8: Q7 | B8: To find studies using learnable or adaptive spike-encoding mechanisms. | C8: "Adaptive encoding" AND "Spiking neural network*" | D8: ="(" & _xlfn.XLOOKUP("Spiking neural network*",'search terms'!B:B,'search terms'!C:C) & ") AND (" & _xlfn.XLOOKUP("Adaptive encoding",'search terms'!B:B,'search terms'!C:C) & ")" -> ("Spiking neural network*" OR "SNN" OR "neuromorphic network*" OR "deep spiking network*" OR "pulsed neural network*" OR "event-driven neural network" OR "event-based spiking network") AND ( "Learnable encoding" OR "Adaptive encoding" OR "learnable spike encoding" OR "adaptive spike encoding" OR "trainable encoder" OR "differentiable encoding" OR "plastic encoding" OR "adaptive threshold encoding" OR "learnable threshold" OR "surrogate gradient") | E8: =ROWS(_xlfn.TEXTSPLIT(D8,," ")) -> 58

Sheet databases
A1: No. | B1: Database | C1: Abbreviation
A2: D1 | B2: IEEE Xplore | C2: ieee
A3: D2 | B3: ACM Digital Library | C3: acm
A4: D3 | B4: Scopus | C4: scopus
A5: D5 | B5: ScienceDirect | C5: scidir
A6: D6 | B6: SpringerLink | C6: springer
A7: D7 | B7: arXiv.org | C7: arxiv

Sheet search hits
A1: Database | B1: Query ID | C1: Query String | D1: Hits | E1: Date | F1: Notes | G1: File Path | H1: Name
A2: IEEE Xplore | B2: Q1 | C2: ("Full Text & Metadata":"Spiking neural network*" OR "Full Text & Metadata":"SNN" OR "Full Text & Metadata":"neuromorphic network*" OR "Full Text & Metadata":"deep spiking network*" OR "Full Text & Metadata":"pulsed neural network*" OR "Full Text & Metadata":"event-driven neural network" OR "Full Text & Metadata":"event-based spiking network") AND ("Full Text & Metadata":"Hybrid ANN-SNN" OR "Full Text & Metadata":"ANN-SNN conversion" OR "Full Text & Metadata":"hybrid neural network*" OR "Full Text & Metadata":"hybrid spiking network*" OR "Full Text & Metadata":"artificial and spiking neural network*") AND ("Full Text & Metadata":"Learnable encoding" OR "Full Text & Metadata":"Adaptive encoding" OR "Full Text & Metadata":"learnable spike encoding" OR "Full Text & Metadata":"adaptive spike encoding" OR "Full Text & Metadata":"trainable encoder" OR "Full Text & Metadata":"differentiable encoding" OR "Full Text & Metadata":"plastic encoding" OR "Full Text & Metadata":"adaptive threshold encoding" OR "Full Text & Metadata":"learnable threshold" OR "Full Text & Metadata":"surrogate gradient") | D2: 13 | E2: 45968 | F2: Advanced search (Full Text & Metadata); Filters Applied: Journals + Early Access+ open access only+ Articles 01/01/2015 - 11/07/2025 | G2: "D:\MyMasterDegreeJourney\Second year\Semester 1\Graduation research\Research logs\Q1" | H2: ieee_q1.bib
A3: ACM Digital Library | B3: Q1 | C3: =_xlfn.XLOOKUP("Q1",queries!A2, queries!D2) -> ("Spiking neural network*" OR "SNN" OR "neuromorphic network*" OR "deep spiking network*" OR "pulsed neural network*" OR "event-driven neural network" OR "event-based spiking network") AND ("Hybrid ANN-SNN" OR "ANN-SNN conversion" OR "hybrid neural network*" OR "hybrid spiking network*" OR "artificial and spiking neural network*") AND ( "Learnable encoding" OR "Adaptive encoding" OR "learnable spike encoding" OR "adaptive spike encoding" OR "trainable encoder" OR "differentiable encoding" OR "plastic encoding" OR "adaptive threshold encoding" OR "learnable threshold" OR "surrogate gradient") | D3: 18 | E3: 45968 | F3: Advanced Search: Search within anywhere; Custom Range (jan-2015; Nov-2025) | G3: "D:\MyMasterDegreeJourney\Second year\Semester 1\Graduation research\Research logs\Q1" | H3: acm_q1.bib
A4: Scopus | B4: Q1 | C4: =_xlfn.XLOOKUP("Q1",queries!A2, queries!D2) -> ("Spiking neural network*" OR "SNN" OR "neuromorphic network*" OR "deep spiking network*" OR "pulsed neural network*" OR "event-driven neural network" OR "event-based spiking network") AND ("Hybrid ANN-SNN" OR "ANN-SNN conversion" OR "hybrid neural network*" OR "hybrid spiking network*" OR "artificial and spiking neural network*") AND ( "Learnable encoding" OR "Adaptive encoding" OR "learnable spike encoding" OR "adaptive spike encoding" OR "trainable encoder" OR "differentiable encoding" OR "plastic encoding" OR "adaptive threshold encoding" OR "learnable threshold" OR "surrogate gradient") | D4: 25 | E4: 45967 | F4: Q1 searched across three fields: (1) All fields – spiking or neuromorphic neural network terms, (2) All fields – hybrid ANN–SNN or conversion terms, and (3) Article title, Abstract, Keywords – learnable/adaptive encoding terms. Filter: Open Access; (2015-2025,English) | G4: "D:\MyMasterDegreeJourney\Second year\Semester 1\Graduation research\Research logs\Q1" | H4: scopus_q1.bib
A5: ScienceDirect | B5: Q1 | C5: ( "Learnable encoding" OR "Adaptive encoding" OR "learnable spike encoding" OR "adaptive spike encoding" OR "trainable encoder" OR "differentiable encoding" OR "adaptive threshold encoding" OR "learnable threshold" OR "surrogate gradient") ("Spiking neural network" OR "SNN" OR "neuromorphic network" OR "deep spiking network" OR "pulsed neural network" OR "event-driven neural network" OR "event-based spiking network") ("Hybrid ANN-SNN" OR "ANN-SNN conversion" OR "hybrid neural network" OR "hybrid spiking network" OR "artificial and spiking neural network") | D5: 2 | E5: 45967 | F5: Q1 searched across three fields: (1) All fields – learnable/adaptive encoding terms, (2) Title/Abstract/Keywords – SNN-related terms, and (3) Title – hybrid ANN–SNN terms. Open Access filter not applide; so all 2 not open access. | G5: "D:\MyMasterDegreeJourney\Second year\Semester 1\Graduation research\Research logs\Q1" | H5: scidir_q1.bib
A6: SpringerLink | B6: Q1 | C6: =_xlfn.XLOOKUP("Q1",queries!A2, queries!D2) -> ("Spiking neural network*" OR "SNN" OR "neuromorphic network*" OR "deep spiking network*" OR "pulsed neural network*" OR "event-driven neural network" OR "event-based spiking network") AND ("Hybrid ANN-SNN" OR "ANN-SNN conversion" OR "hybrid neural network*" OR "hybrid spiking network*" OR "artificial and spiking neural network*") AND ( "Learnable encoding" OR "Adaptive encoding" OR "learnable spike encoding" OR "adaptive spike encoding" OR "trainable encoder" OR "differentiable encoding" OR "plastic encoding" OR "adaptive threshold encoding" OR "learnable threshold" OR "surrogate gradient") | D6: 11 | E6: 45967 | F6: advanced search across all fields (title, abstract, keywords, and full text); Filters: custom dates (2015-2025); English; Open access | G6: "D:\MyMasterDegreeJourney\Second year\Semester 1\Graduation research\Research logs\Q1" | H6: springer_q1.bib
A7: arXiv.org | B7: Q1 | C7: =_xlfn.XLOOKUP("Q1",queries!A2, queries!D2) -> ("Spiking neural network*" OR "SNN" OR "neuromorphic network*" OR "deep spiking network*" OR "pulsed neural network*" OR "event-driven neural network" OR "event-based spiking network") AND ("Hybrid ANN-SNN" OR "ANN-SNN conversion" OR "hybrid neural network*" OR "hybrid spiking network*" OR "artificial and spiking neural network*") AND ( "Learnable encoding" OR "Adaptive encoding" OR "learnable spike encoding" OR "adaptive spike encoding" OR "trainable encoder" OR "differentiable encoding" OR "plastic encoding" OR "adaptive threshold encoding" OR "learnable threshold" OR "surrogate gradient") | D7: 5 | E7: 45967 | F7: advanced search across all fields (title, abstract, keywords, and full text); custom dates (2015-2025) | G7: "D:\MyMasterDegreeJourney\Second year\Semester 1\Graduation research\Research logs\Q1" | H7: acm_q1.bib
A8: IEEE Xplore | B8: Q2 | C8: ("Full Text & Metadata":"Learnable encoding" OR "Full Text & Metadata":"Adaptive encoding" OR "Full Text & Metadata":"learnable spike encoding" OR "Full Text & Metadata":"adaptive spike encoding" OR "Full Text & Metadata":"trainable encoder" OR "Full Text & Metadata":"differentiable encoding" OR "Full Text & Metadata":"plastic encoding" OR "Full Text & Metadata":"adaptive threshold encoding" OR "Full Text & Metadata":"learnable threshold" OR "Full Text & Metadata":"surrogate gradient") AND ("Full Text & Metadata":"event-based dataset*" OR "Full Text & Metadata":"DVS Gesture" OR "Full Text & Metadata":"N-MNIST" OR "Full Text & Metadata":"SHD" OR "Full Text & Metadata":"Spiking Heidelberg Digits" OR "Full Text & Metadata":"CIFAR-10-DVS" OR "Full Text & Metadata":"neuromorphic benchmark") AND ("Full Text & Metadata":"TTFS" OR "Full Text & Metadata":"time-to-first-spike" OR "Full Text & Metadata":"static" OR "Full Text & Metadata":"hand-crafted" OR "Full Text & Metadata":"conventional" OR "Full Text & Metadata":"rule-based" OR "Full Text & Metadata":"traditional encoding" OR "Full Text & Metadata":"rate" OR "Full Text & Metadata":"temporal encoding" OR "Full Text & Metadata":"population encoding" OR "Full Text & Metadata":"direct encoding" OR "Full Text & Metadata":"latency" OR "Full Text & Metadata":"fixed threshold" OR "Full Text & Metadata":"non-adaptive" OR "Full Text & Metadata":"Poisson") | D8: 18 | E8: 45967 | F8: Advanced search (Full Text & Metadata); Filters Applied: Journals + Early Access+ open access only+ Articles 01/01/2015 - 11/07/2025 | G8: "D:\MyMasterDegreeJourney\Second year\Semester 1\Graduation research\Research logs\Q2" | H8: ieee_q2.bib
A9: ACM Digital Library | B9: Q2 | C9: =_xlfn.XLOOKUP("Q2",queries!A3, queries!D3) -> ( "Learnable encoding" OR "Adaptive encoding" OR "learnable spike encoding" OR "adaptive spike encoding" OR "trainable encoder" OR "differentiable encoding" OR "plastic encoding" OR "adaptive threshold encoding" OR "learnable threshold" OR "surrogate gradient") AND ("event-based dataset*" OR "DVS Gesture" OR "N-MNIST" OR "SHD" OR "Spiking Heidelberg Digits" OR "CIFAR-10-DVS" OR "neuromorphic benchmark") AND ("TTFS" OR "time-to-first-spike" OR "static" OR "hand-crafted" OR "conventional" OR "rule-based" OR "traditional encoding" OR "rate" OR "temporal encoding" OR "population encoding" OR "direct encoding" OR "latency" OR "fixed threshold" OR "non-adaptive" OR "Poisson") | D9: 17 | E9: 45967 | F9: Advanced Search: Search within anywhere; filters: Proceedings, Research Article, January 2015 - November 2025 | G9: "D:\MyMasterDegreeJourney\Second year\Semester 1\Graduation research\Research logs\Q2" | H9: acm_q2.bib
A10: Scopus | B10: Q2 | C10: TITLE-ABS-KEY ( ( "Learnable encoding" OR "Adaptive encoding" OR "learnable spike encoding" OR "adaptive spike encoding" OR "trainable encoder" OR "differentiable encoding" OR "plastic encoding" OR "adaptive threshold encoding" OR "learnable threshold" OR "surrogate gradient" ) AND ( "event-based dataset*" OR "DVS Gesture" OR "N-MNIST" OR "SHD" OR "Spiking Heidelberg Digits" OR "CIFAR-10-DVS" OR "neuromorphic benchmark" ) AND ( "TTFS" OR "time-to-first-spike" OR "static" OR "hand-crafted" OR "conventional" OR "rule-based" OR "traditional encoding" OR "rate" OR "temporal encoding" OR "population encoding" OR "direct encoding" OR "latency" OR "fixed threshold" OR "non-adaptive" OR "Poisson" ) ) AND PUBYEAR > 2014 AND PUBYEAR < 2025 AND ( LIMIT-TO ( OA , "all" ) OR LIMIT-TO ( OA , "publisherfullgold" ) OR LIMIT-TO ( OA , "repository" ) ) AND ( LIMIT-TO ( LANGUAGE , "English" ) ) | D10: 4 | E10: 45967 | F10: Advanced search (TITLE-ABS-KEY); filter applied: limited to English, All open access => includes Gold, Green, Hybrid gold | G10: "D:\MyMasterDegreeJourney\Second year\Semester 1\Graduation research\Research logs\Q2" | H10: scopus_q2.bib
A11: ScienceDirect | B11: Q2 | C11: ( "Learnable encoding" OR "Adaptive encoding" OR "learnable spike encoding" OR "adaptive spike encoding" OR "trainable encoder" OR "differentiable encoding" OR "adaptive threshold encoding" OR "learnable threshold" OR "surrogate gradient") ("event-based dataset" OR "DVS Gesture" OR "N-MNIST" OR "SHD" OR "Spiking Heidelberg Digits" OR "CIFAR-10-DVS") AND ("TTFS" OR "time-to-first-spike" OR "static" ) | D11: 2 | E11: 45967 | F11: Q2 searched using two sub-queries: (1) Title/Abstract/Keywords – learnable/adaptive encoding terms, and (2) All Fields – event-based dataset and temporal-encoding terms (e.g., TTFS, static). Filter: Open Access. | G11: "D:\MyMasterDegreeJourney\Second year\Semester 1\Graduation research\Research logs\Q2" | H11: scidir_q2.bib
A12: SpringerLink | B12: Q2 | C12: =_xlfn.XLOOKUP("Q2",queries!A3, queries!D3) -> ( "Learnable encoding" OR "Adaptive encoding" OR "learnable spike encoding" OR "adaptive spike encoding" OR "trainable encoder" OR "differentiable encoding" OR "plastic encoding" OR "adaptive threshold encoding" OR "learnable threshold" OR "surrogate gradient") AND ("event-based dataset*" OR "DVS Gesture" OR "N-MNIST" OR "SHD" OR "Spiking Heidelberg Digits" OR "CIFAR-10-DVS" OR "neuromorphic benchmark") AND ("TTFS" OR "time-to-first-spike" OR "static" OR "hand-crafted" OR "conventional" OR "rule-based" OR "traditional encoding" OR "rate" OR "temporal encoding" OR "population encoding" OR "direct encoding" OR "latency" OR "fixed threshold" OR "non-adaptive" OR "Poisson") | D12: 15 | E12: 45967 | F12: advanced search across all fields (title, abstract, keywords, and full text); limited to publications written in English, published between 2015 and 2025, and classified as Articles, Research Articles, Conference Papers, or Review Articles. The Open Access filter was also applied to ensure accessibility. | G12: "D:\MyMasterDegreeJourney\Second year\Semester 1\Graduation research\Research logs\Q2" | H12: springer_q2.bib
A13: arXiv.org | B13: Q2 | C13: =_xlfn.XLOOKUP("Q2",queries!A3, queries!D3) -> ( "Learnable encoding" OR "Adaptive encoding" OR "learnable spike encoding" OR "adaptive spike encoding" OR "trainable encoder" OR "differentiable encoding" OR "plastic encoding" OR "adaptive threshold encoding" OR "learnable threshold" OR "surrogate gradient") AND ("event-based dataset*" OR "DVS Gesture" OR "N-MNIST" OR "SHD" OR "Spiking Heidelberg Digits" OR "CIFAR-10-DVS" OR "neuromorphic benchmark") AND ("TTFS" OR "time-to-first-spike" OR "static" OR "hand-crafted" OR "conventional" OR "rule-based" OR "traditional encoding" OR "rate" OR "temporal encoding" OR "population encoding" OR "direct encoding" OR "latency" OR "fixed threshold" OR "non-adaptive" OR "Poisson") | D13: 5 | E13: 45967 | F13: advanced search across all fields (title, abstract, keywords, and full text); custom dates (2015-2025) | G13: "D:\MyMasterDegreeJourney\Second year\Semester 1\Graduation research\Research logs\Q2" | H13: arxiv_q2.bib
A14: IEEE Xplore | B14: Q3 | C14: ("Full Text & Metadata":"event-based dataset*" OR "Full Text & Metadata":"DVS Gesture" OR "Full Text & Metadata":"N-MNIST" OR "Full Text & Metadata":"SHD" OR "Full Text & Metadata":"Spiking Heidelberg Digits" OR "Full Text & Metadata":"CIFAR-10-DVS" OR "Full Text & Metadata":"neuromorphic benchmark") AND ("Full Text & Metadata":"software simulation" OR "Full Text & Metadata":"neuromorphic hardware" OR "Full Text & Metadata":"Loihi" OR "Full Text & Metadata":"SpiNNaker" OR "Full Text & Metadata":"TrueNorth" OR "Full Text & Metadata":"BindsNET" OR "Full Text & Metadata":"snnTorch" OR "Full Text & Metadata":"neuromorphic simulator") AND ("Full Text & Metadata":"Learnable encoding" OR "Full Text & Metadata":"Adaptive encoding" OR "Full Text & Metadata":"learnable spike encoding" OR "Full Text & Metadata":"adaptive spike encoding" OR "Full Text & Metadata":"trainable encoder" OR "Full Text & Metadata":"differentiable encoding" OR "Full Text & Metadata":"plastic encoding" OR "Full Text & Metadata":"adaptive threshold encoding" OR "Full Text & Metadata":"learnable threshold" OR "Full Text & Metadata":"surrogate gradient") | D14: 15 | E14: 45967 | F14: Advanced search (Full Text & Metadata); Filters Applied: Journals + Early Access+ open access only+ Articles 01/01/2015 - 11/07/2025 | G14: "D:\MyMasterDegreeJourney\Second year\Semester 1\Graduation research\Research logs\Q3" | H14: ieee_q3.bib
A15: ACM Digital Library | B15: Q3 | C15: =_xlfn.XLOOKUP("Q3",queries!A4, queries!D4) -> ("event-based dataset*" OR "DVS Gesture" OR "N-MNIST" OR "SHD" OR "Spiking Heidelberg Digits" OR "CIFAR-10-DVS" OR "neuromorphic benchmark") AND ("software simulation" OR "neuromorphic hardware" OR "Loihi" OR "SpiNNaker" OR "TrueNorth" OR "BindsNET" OR "snnTorch" OR "neuromorphic simulator") AND ( "Learnable encoding" OR "Adaptive encoding" OR "learnable spike encoding" OR "adaptive spike encoding" OR "trainable encoder" OR "differentiable encoding" OR "plastic encoding" OR "adaptive threshold encoding" OR "learnable threshold" OR "surrogate gradient") | D15: 22 | E15: 45967 | F15: Advanced search (Full Text & Metadata); Filters Applied: Journals + Early Access+ open access only+ Articles 01/01/2015 - 11/07/2025 | G15: "D:\MyMasterDegreeJourney\Second year\Semester 1\Graduation research\Research logs\Q3" | H15: acm_q3.bib
A16: Scopus | B16: Q3 | C16: TITLE-ABS-KEY ( ( "event-based dataset*" OR "DVS Gesture" OR "N-MNIST" OR "SHD" OR "Spiking Heidelberg Digits" OR "CIFAR-10-DVS" OR "neuromorphic benchmark" ) AND ( "software simulation" OR "neuromorphic hardware" OR "Loihi" OR "SpiNNaker" OR "TrueNorth" OR "BindsNET" OR "snnTorch" OR "neuromorphic simulator" ) AND ( "Learnable encoding" OR "Adaptive encoding" OR "learnable spike encoding" OR "adaptive spike encoding" OR "trainable encoder" OR "differentiable encoding" OR "plastic encoding" OR "adaptive threshold encoding" OR "learnable threshold" OR "surrogate gradient" ) ) AND PUBYEAR > 2019 AND PUBYEAR < 2026 AND ( LIMIT-TO ( LANGUAGE , "English" ) ) AND ( LIMIT-TO ( OA , "all" ) OR LIMIT-TO ( OA , "repository" ) OR LIMIT-TO ( OA , "publisherfullgold" ) ) | D16: 3 | E16: 45967 | F16: Advanced search (TITLE-ABS-KEY); filter applied: limited to English, All open access => includes Gold, Green, Hybrid gold | G16: "D:\MyMasterDegreeJourney\Second year\Semester 1\Graduation research\Research logs\Q3" | H16: scopus_q3.bib
A17: ScienceDirect | B17: Q3 | C17: "Learnable encoding" OR "Adaptive encoding" OR "learnable spike encoding" OR "adaptive spike encoding" OR "trainable encoder" OR "differentiable encoding" OR "adaptive threshold encoding" OR "learnable threshold" OR "surrogate gradient" "event-based dataset" OR "DVS Gesture" OR "N-MNIST" OR "SHD" OR "Spiking Heidelberg Digits" OR "CIFAR-10-DVS" OR "neuromorphic benchmark" OR "software simulation" OR "neuromorphic hardware" | D17: 11 | E17: 45967 | F17: Q3 searched across two fields: (1) All Fields – learnable/adaptive encoding terms, and (2) Title/Abstract/Keywords – event-based dataset and neuromorphic system terms (e.g., software simulation, hardware). Filter: Open Access. | G17: "D:\MyMasterDegreeJourney\Second year\Semester 1\Graduation research\Research logs\Q3" | H17: scidir_q3.bib
A18: SpringerLink | B18: Q3 | C18: =_xlfn.XLOOKUP("Q3",queries!A4, queries!D4) -> ("event-based dataset*" OR "DVS Gesture" OR "N-MNIST" OR "SHD" OR "Spiking Heidelberg Digits" OR "CIFAR-10-DVS" OR "neuromorphic benchmark") AND ("software simulation" OR "neuromorphic hardware" OR "Loihi" OR "SpiNNaker" OR "TrueNorth" OR "BindsNET" OR "snnTorch" OR "neuromorphic simulator") AND ( "Learnable encoding" OR "Adaptive encoding" OR "learnable spike encoding" OR "adaptive spike encoding" OR "trainable encoder" OR "differentiable encoding" OR "plastic encoding" OR "adaptive threshold encoding" OR "learnable threshold" OR "surrogate gradient") | D18: 12 | E18: 45967 | F18: advanced search across all fields (title, abstract, keywords, and full text); limited to publications written in English, published between 2015 and 2025, and classified as Articles, Research Articles, Conference Papers, or Review Articles. The Open Access filter was also applied to ensure accessibility. | G18: "D:\MyMasterDegreeJourney\Second year\Semester 1\Graduation research\Research logs\Q3" | H18: springer_q3.bib
A19: arXiv.org | B19: Q3 | C19: =_xlfn.XLOOKUP("Q3",queries!A4, queries!D4) -> ("event-based dataset*" OR "DVS Gesture" OR "N-MNIST" OR "SHD" OR "Spiking Heidelberg Digits" OR "CIFAR-10-DVS" OR "neuromorphic benchmark") AND ("software simulation" OR "neuromorphic hardware" OR "Loihi" OR "SpiNNaker" OR "TrueNorth" OR "BindsNET" OR "snnTorch" OR "neuromorphic simulator") AND ( "Learnable encoding" OR "Adaptive encoding" OR "learnable spike encoding" OR "adaptive spike encoding" OR "trainable encoder" OR "differentiable encoding" OR "plastic encoding" OR "adaptive threshold encoding" OR "learnable threshold" OR "surrogate gradient") | D19: 2 | E19: 45967 | F19: advanced search across all fields (title, abstract, keywords, and full text); custom dates (2015-2025) | G19: "D:\MyMasterDegreeJourney\Second year\Semester 1\Graduation research\Research logs\Q3" | H19: arxiv_q3.bib
A20: IEEE Xplore | B20: Q4 | C20: ("All Metadata":"Learnable encoding" OR "All Metadata":"Adaptive encoding" OR "All Metadata":"learnable spike encoding" OR "All Metadata":"adaptive spike encoding" OR "All Metadata":"trainable encoder" OR "All Metadata":"differentiable encoding" OR "All Metadata":"plastic encoding" OR "All Metadata":"adaptive threshold encoding" OR "All Metadata":"learnable threshold" OR "All Metadata":"surrogate gradient") AND ("All Metadata":"Spiking neural network*" OR "All Metadata":"SNN" OR "All Metadata":"neuromorphic network*" OR "All Metadata":"deep spiking network*" OR "All Metadata":"pulsed neural network*" OR "All Metadata":"event-driven neural network" OR "All Metadata":"event-based spiking network") AND ("All Metadata":"software simulation" OR "All Metadata":"neuromorphic hardware" OR "All Metadata":"Loihi" OR "All Metadata":"SpiNNaker" OR "All Metadata":"TrueNorth" OR "All Metadata":"BindsNET" OR "All Metadata":"snnTorch" OR "All Metadata":"neuromorphic simulator") | D20: 2 | E20: 45967 | F20: Advanced search (ALL Metadata); Filters Applied: Journals + open access only + Articles 01/01/2015 - 11/07/2025 | G20: "D:\MyMasterDegreeJourney\Second year\Semester 1\Graduation research\Research logs\Q4" | H20: ieee_q4.bib
A21: ACM Digital Library | B21: Q4 | C21: =_xlfn.XLOOKUP("Q4",queries!A5, queries!D5) -> ( "Learnable encoding" OR "Adaptive encoding" OR "learnable spike encoding" OR "adaptive spike encoding" OR "trainable encoder" OR "differentiable encoding" OR "plastic encoding" OR "adaptive threshold encoding" OR "learnable threshold" OR "surrogate gradient") AND ("Spiking neural network*" OR "SNN" OR "neuromorphic network*" OR "deep spiking network*" OR "pulsed neural network*" OR "event-driven neural network" OR "event-based spiking network") AND ("software simulation" OR "neuromorphic hardware" OR "Loihi" OR "SpiNNaker" OR "TrueNorth" OR "BindsNET" OR "snnTorch" OR "neuromorphic simulator") | D21: 16 | E21: 45967 | F21: Searched for learnable/adaptive encoding terms in All Fields, combined with spiking neural network and hardware/simulation terms searched in the Abstract. Filter: publication years 2015–2025 | G21: "D:\MyMasterDegreeJourney\Second year\Semester 1\Graduation research\Research logs\Q4" | H21: acm_q4.bib
A22: Scopus | B22: Q4 | C22: TITLE-ABS-KEY ( ( "Learnable encoding" OR "Adaptive encoding" OR "learnable spike encoding" OR "adaptive spike encoding" OR "trainable encoder" OR "differentiable encoding" OR "plastic encoding" OR "adaptive threshold encoding" OR "learnable threshold" OR "surrogate gradient" ) AND ( "Spiking neural network*" OR "SNN" OR "neuromorphic network*" OR "deep spiking network*" OR "pulsed neural network*" OR "event-driven neural network" OR "event-based spiking network" ) AND ( "software simulation" OR "neuromorphic hardware" OR "Loihi" OR "SpiNNaker" OR "TrueNorth" OR "BindsNET" OR "snnTorch" OR "neuromorphic simulator" ) ) AND PUBYEAR > 2014 AND PUBYEAR < 2026 AND PUBYEAR > 2019 AND PUBYEAR < 2026 AND ( LIMIT-TO ( OA , "all" ) OR LIMIT-TO ( OA , "publisherfullgold" ) OR LIMIT-TO ( OA , "publisherhybridgold" ) OR LIMIT-TO ( OA , "repository" ) ) AND ( LIMIT-TO ( DOCTYPE , "ar" ) OR LIMIT-TO ( DOCTYPE , "cp" ) OR LIMIT-TO ( DOCTYPE , "re" ) ) AND ( LIMIT-TO ( LANGUAGE , "English" ) ) | D22: 22 | E22: 45967 | F22: Queried TITLE-ABS-KEY for three concept blocks — (learnable/adaptive encoding terms) AND (spiking/neuromorphic network terms) AND (software simulation / neuromorphic hardware & tools: Loihi, SpiNNaker, TrueNorth, BindsNET, snnTorch, etc.). Years: 2020–2025 (PUBYEAR > 2019 & < 2026). Access: Open Access only (all OA types: publisher full gold, repository/green, hybrid gold). Language: English. Document types: Article (ar), Conference Paper (cp), Review (re). | G22: "D:\MyMasterDegreeJourney\Second year\Semester 1\Graduation research\Research logs\Q4" | H22: scopus_q4.bib
A23: ScienceDirect | B23: Q4 | C23: ("Learnable encoding" OR "Adaptive encoding" OR "learnable spike encoding" OR "adaptive spike encoding" OR "trainable encoder" OR "differentiable encoding" OR "adaptive threshold encoding" OR "learnable threshold" OR "surrogate gradient") ("software simulation" OR "neuromorphic hardware" OR "Loihi" OR "SpiNNaker" OR "TrueNorth" OR "BindsNET" OR "snnTorch" OR "neuromorphic simulator") ("Spiking neural network" OR "SNN" OR "neuromorphic network" OR "deep spiking network" OR "pulsed neural network" OR "event-driven neural network") | D23: 3 | E23: 45967 | F23: Q4 searched across 3 fields: (1) All Fields – learnable/adaptive encoding term; and (2) on Title/Abstract/Keywords software simulation terms ; and (3) searched in Title only: Spiking neural network terms, Filter: Open Access. (2015,2025) | G23: "D:\MyMasterDegreeJourney\Second year\Semester 1\Graduation research\Research logs\Q4" | H23: scidir_q4.bib
A24: SpringerLink | B24: Q4 | C24: =_xlfn.XLOOKUP("Q4",queries!A5, queries!D5) -> ( "Learnable encoding" OR "Adaptive encoding" OR "learnable spike encoding" OR "adaptive spike encoding" OR "trainable encoder" OR "differentiable encoding" OR "plastic encoding" OR "adaptive threshold encoding" OR "learnable threshold" OR "surrogate gradient") AND ("Spiking neural network*" OR "SNN" OR "neuromorphic network*" OR "deep spiking network*" OR "pulsed neural network*" OR "event-driven neural network" OR "event-based spiking network") AND ("software simulation" OR "neuromorphic hardware" OR "Loihi" OR "SpiNNaker" OR "TrueNorth" OR "BindsNET" OR "snnTorch" OR "neuromorphic simulator") | D24: 36 | E24: 45967 | F24: Q4: Queried All Fields; Document type – Article, Research article, Review article; Publication year – 2015 to 2025; Language – English; Access type – Open Access only. | G24: "D:\MyMasterDegreeJourney\Second year\Semester 1\Graduation research\Research logs\Q4" | H24: springer_q4.bib
A25: arXiv.org | B25: Q4 | C25: =_xlfn.XLOOKUP("Q4",queries!A5, queries!D5) -> ( "Learnable encoding" OR "Adaptive encoding" OR "learnable spike encoding" OR "adaptive spike encoding" OR "trainable encoder" OR "differentiable encoding" OR "plastic encoding" OR "adaptive threshold encoding" OR "learnable threshold" OR "surrogate gradient") AND ("Spiking neural network*" OR "SNN" OR "neuromorphic network*" OR "deep spiking network*" OR "pulsed neural network*" OR "event-driven neural network" OR "event-based spiking network") AND ("software simulation" OR "neuromorphic hardware" OR "Loihi" OR "SpiNNaker" OR "TrueNorth" OR "BindsNET" OR "snnTorch" OR "neuromorphic simulator") | D25: 26 | E25: 45967 | F25: Queried the Abstract field only; (2015-2025) | G25: "D:\MyMasterDegreeJourney\Second year\Semester 1\Graduation research\Research logs\Q4" | H25: arxiv_q4.bib
A26: IEEE Xplore | B26: Q5 | C26: ("Full Text & Metadata":("Spiking neural network*" OR "Full Text & Metadata":"SNN" OR "Full Text & Metadata":"neuromorphic network*" OR "Full Text & Metadata":"deep spiking network*" OR "Full Text & Metadata":"pulsed neural network*" OR "Full Text & Metadata":"event-driven neural network" OR "Full Text & Metadata":"event-based spiking network")) AND ("Full Text & Metadata":("Hybrid ANN-SNN" OR "Full Text & Metadata":"ANN-SNN conversion" OR "Full Text & Metadata":"hybrid neural network*" OR "Full Text & Metadata":"hybrid spiking network*" OR "Full Text & Metadata":"artificial and spiking neural network*")) AND ("Full Text & Metadata":("event-based dataset*" OR "Full Text & Metadata":"DVS Gesture" OR "Full Text & Metadata":"N-MNIST" OR "Full Text & Metadata":"SHD" OR "Full Text & Metadata":"Spiking Heidelberg Digits" OR "Full Text & Metadata":"CIFAR-10-DVS" OR "Full Text & Metadata":"neuromorphic benchmark")) AND ("Full Text & Metadata":("TTFS" OR "Full Text & Metadata":"time-to-first-spike" OR "Full Text & Metadata":"static" OR "Full Text & Metadata":"hand-crafted" OR "Full Text & Metadata":"conventional" OR "Full Text & Metadata":"rule-based" OR "Full Text & Metadata":"traditional encoding" OR "Full Text & Metadata":"rate" OR "Full Text & Metadata":"temporal encoding" OR "Full Text & Metadata":"population encoding" OR "Full Text & Metadata":"direct encoding" OR "Full Text & Metadata":"latency" OR "Full Text & Metadata":"fixed threshold" OR "Full Text & Metadata":"non-adaptive" OR "Full Text & Metadata":"Poisson")) | D26: 0 | E26: 45967 | F26: Queried the Full Text & Metadata field for four concept groups: Spiking, Hybrid architectures ,Datasets , traditnal encoding Field searched: Full Text & Metadata (broad coverage including title, abstract, and indexed metadata). Filters: none applied for year, access type, or language at query stage. | G26: "D:\MyMasterDegreeJourney\Second year\Semester 1\Graduation research\Research logs\Q5" | H26: ieee_q5.bib
A27: ACM Digital Library | B27: Q5 | C27: =_xlfn.XLOOKUP("Q5",queries!A6, queries!D6) -> ("Spiking neural network*" OR "SNN" OR "neuromorphic network*" OR "deep spiking network*" OR "pulsed neural network*" OR "event-driven neural network" OR "event-based spiking network") AND ("Hybrid ANN-SNN" OR "ANN-SNN conversion" OR "hybrid neural network*" OR "hybrid spiking network*" OR "artificial and spiking neural network*") AND ("event-based dataset*" OR "DVS Gesture" OR "N-MNIST" OR "SHD" OR "Spiking Heidelberg Digits" OR "CIFAR-10-DVS" OR "neuromorphic benchmark") AND ("TTFS" OR "time-to-first-spike" OR "static" OR "hand-crafted" OR "conventional" OR "rule-based" OR "traditional encoding" OR "rate" OR "temporal encoding" OR "population encoding" OR "direct encoding" OR "latency" OR "fixed threshold" OR "non-adaptive" OR "Poisson") | D27: 11 | E27: 45967 | F27: Field searched: All Fields (includes title, abstract, and metadata). Filters: (2015-2025) | G27: "D:\MyMasterDegreeJourney\Second year\Semester 1\Graduation research\Research logs\Q5" | H27: acm_q5.bib
A28: Scopus | B28: Q5 | C28: =_xlfn.XLOOKUP("Q5",queries!A6, queries!D6) -> ("Spiking neural network*" OR "SNN" OR "neuromorphic network*" OR "deep spiking network*" OR "pulsed neural network*" OR "event-driven neural network" OR "event-based spiking network") AND ("Hybrid ANN-SNN" OR "ANN-SNN conversion" OR "hybrid neural network*" OR "hybrid spiking network*" OR "artificial and spiking neural network*") AND ("event-based dataset*" OR "DVS Gesture" OR "N-MNIST" OR "SHD" OR "Spiking Heidelberg Digits" OR "CIFAR-10-DVS" OR "neuromorphic benchmark") AND ("TTFS" OR "time-to-first-spike" OR "static" OR "hand-crafted" OR "conventional" OR "rule-based" OR "traditional encoding" OR "rate" OR "temporal encoding" OR "population encoding" OR "direct encoding" OR "latency" OR "fixed threshold" OR "non-adaptive" OR "Poisson") | D28: 22 | E28: 45967 | F28: Field searched: All Fields (includes title, abstract, and metadata), (2015-2025), open access, english | G28: "D:\MyMasterDegreeJourney\Second year\Semester 1\Graduation research\Research logs\Q5" | H28: scopus_q5.bib
A29: ScienceDirect | B29: Q5 | C29: Spiking neural network OR "SNN" OR "neuromorphic network" OR "deep spiking network" OR "pulsed neural network" OR "event-driven neural network" OR "event-based spiking network" AND ("event-based dataset" OR "neuromorphic benchmark" ) "TTFS" OR "time-to-first-spike" OR "traditional encoding" OR "rate" OR "temporal encoding" OR "population encoding" OR "fixed threshold" OR "non-adaptive" OR "Poisson" ("Hybrid ANN-SNN" OR "ANN-SNN conversion" OR "hybrid neural network" OR "hybrid spiking network" OR "artificial and spiking neural network") | D29: 1 | E29: 45967 | F29: Q5: 3 PARTS =>query execution across three fields: All fields – general SNN and dataset terms. Title/Abstract/Keywords – encoding mechanism terms. Title only – hybrid ANN–SNN relationship terms. Filters Applied: Year range: 2015–2025 Language: English Access type: Open Access | G29: "D:\MyMasterDegreeJourney\Second year\Semester 1\Graduation research\Research logs\Q5" | H29: scidir_q5.bib
A30: SpringerLink | B30: Q5 | C30: =_xlfn.XLOOKUP("Q5",queries!A6, queries!D6) -> ("Spiking neural network*" OR "SNN" OR "neuromorphic network*" OR "deep spiking network*" OR "pulsed neural network*" OR "event-driven neural network" OR "event-based spiking network") AND ("Hybrid ANN-SNN" OR "ANN-SNN conversion" OR "hybrid neural network*" OR "hybrid spiking network*" OR "artificial and spiking neural network*") AND ("event-based dataset*" OR "DVS Gesture" OR "N-MNIST" OR "SHD" OR "Spiking Heidelberg Digits" OR "CIFAR-10-DVS" OR "neuromorphic benchmark") AND ("TTFS" OR "time-to-first-spike" OR "static" OR "hand-crafted" OR "conventional" OR "rule-based" OR "traditional encoding" OR "rate" OR "temporal encoding" OR "population encoding" OR "direct encoding" OR "latency" OR "fixed threshold" OR "non-adaptive" OR "Poisson") | D30: 6 | E30: 45967 | F30: Filters Applied: Content Type: Article, Research Article, Conference Paper, Review Article Language: English Access Type: Open Access Publication Year Range: 2015 – 2025 | G30: "D:\MyMasterDegreeJourney\Second year\Semester 1\Graduation research\Research logs\Q5" | H30: springer_q5.bib
A31: arXiv.org | B31: Q5 | C31: =_xlfn.XLOOKUP("Q5",queries!A6, queries!D6) -> ("Spiking neural network*" OR "SNN" OR "neuromorphic network*" OR "deep spiking network*" OR "pulsed neural network*" OR "event-driven neural network" OR "event-based spiking network") AND ("Hybrid ANN-SNN" OR "ANN-SNN conversion" OR "hybrid neural network*" OR "hybrid spiking network*" OR "artificial and spiking neural network*") AND ("event-based dataset*" OR "DVS Gesture" OR "N-MNIST" OR "SHD" OR "Spiking Heidelberg Digits" OR "CIFAR-10-DVS" OR "neuromorphic benchmark") AND ("TTFS" OR "time-to-first-spike" OR "static" OR "hand-crafted" OR "conventional" OR "rule-based" OR "traditional encoding" OR "rate" OR "temporal encoding" OR "population encoding" OR "direct encoding" OR "latency" OR "fixed threshold" OR "non-adaptive" OR "Poisson") | D31: 2 | E31: 45967 | F31: advanced search across all fields (title, abstract, keywords, and full text); custom dates (2015-2025) | G31: "D:\MyMasterDegreeJourney\Second year\Semester 1\Graduation research\Research logs\Q5" | H31: arxiv_q5.bib
A32: IEEE Xplore | B32: Q6 | C32: =_xlfn.XLOOKUP("Q6",queries!A7, queries!D7) -> ("Spiking neural network*" OR "SNN" OR "neuromorphic network*" OR "deep spiking network*" OR "pulsed neural network*" OR "event-driven neural network" OR "event-based spiking network") AND ("Hybrid ANN-SNN" OR "ANN-SNN conversion" OR "hybrid neural network*" OR "hybrid spiking network*" OR "artificial and spiking neural network*") AND ("software simulation" OR "neuromorphic hardware" OR "Loihi" OR "SpiNNaker" OR "TrueNorth" OR "BindsNET" OR "snnTorch" OR "neuromorphic simulator") | D32: 0 | E32: 45967 | F32: 18 after open access filter produce no result | G32: "D:\MyMasterDegreeJourney\Second year\Semester 1\Graduation research\Research logs\Q6" | H32: ieee_q6.bib
A33: ACM Digital Library | B33: Q6 | C33: =_xlfn.XLOOKUP("Q6",queries!A7, queries!D7) -> ("Spiking neural network*" OR "SNN" OR "neuromorphic network*" OR "deep spiking network*" OR "pulsed neural network*" OR "event-driven neural network" OR "event-based spiking network") AND ("Hybrid ANN-SNN" OR "ANN-SNN conversion" OR "hybrid neural network*" OR "hybrid spiking network*" OR "artificial and spiking neural network*") AND ("software simulation" OR "neuromorphic hardware" OR "Loihi" OR "SpiNNaker" OR "TrueNorth" OR "BindsNET" OR "snnTorch" OR "neuromorphic simulator") | D33: 30 | E33: 45967 | F33: 2015- 2025 | G33: "D:\MyMasterDegreeJourney\Second year\Semester 1\Graduation research\Research logs\Q6" | H33: acm_q6.bib
A34: Scopus | B34: Q6 | C34: =_xlfn.XLOOKUP("Q6",queries!A7, queries!D7) -> ("Spiking neural network*" OR "SNN" OR "neuromorphic network*" OR "deep spiking network*" OR "pulsed neural network*" OR "event-driven neural network" OR "event-based spiking network") AND ("Hybrid ANN-SNN" OR "ANN-SNN conversion" OR "hybrid neural network*" OR "hybrid spiking network*" OR "artificial and spiking neural network*") AND ("software simulation" OR "neuromorphic hardware" OR "Loihi" OR "SpiNNaker" OR "TrueNorth" OR "BindsNET" OR "snnTorch" OR "neuromorphic simulator") | D34: 7 | E34: 45967 | F34: Field searched: (title, abstract, and keywords), (2015-2025), open access, english | G34: "D:\MyMasterDegreeJourney\Second year\Semester 1\Graduation research\Research logs\Q6" | H34: scopus_q6.bib
A35: ScienceDirect | B35: Q6 | C35: "Spiking neural network" OR "SNN" OR "neuromorphic network" OR "deep spiking network" OR "pulsed neural network" OR "event-driven neural network" OR "event-based spiking network" "software simulation" OR "neuromorphic hardware" OR "Loihi" OR "SpiNNaker" OR "TrueNorth" OR "BindsNET" OR "snnTorch" OR "neuromorphic simulator" "Hybrid ANN-SNN" OR "ANN-SNN conversion" OR "hybrid neural network" OR "hybrid spiking network" OR "artificial and spiking neural network" | D35: 1 | E35: 45967 | F35: Q5: 3 PARTS =>query execution across three fields: All fields – general SNN terms. Title/Abstract/Keywords – software simulation terms. Title only – hybrid ANN–SNN relationship terms. Filters Applied: Year range: 2015–2025 Language: English Access type: Open Access | G35: "D:\MyMasterDegreeJourney\Second year\Semester 1\Graduation research\Research logs\Q6" | H35: scidir_q6.bib
A36: SpringerLink | B36: Q6 | C36: =_xlfn.XLOOKUP("Q6",queries!A7, queries!D7) -> ("Spiking neural network*" OR "SNN" OR "neuromorphic network*" OR "deep spiking network*" OR "pulsed neural network*" OR "event-driven neural network" OR "event-based spiking network") AND ("Hybrid ANN-SNN" OR "ANN-SNN conversion" OR "hybrid neural network*" OR "hybrid spiking network*" OR "artificial and spiking neural network*") AND ("software simulation" OR "neuromorphic hardware" OR "Loihi" OR "SpiNNaker" OR "TrueNorth" OR "BindsNET" OR "snnTorch" OR "neuromorphic simulator") | D36: 13 | E36: 45967 | F36: Filter: Open Access. (2015,2025) | G36: "D:\MyMasterDegreeJourney\Second year\Semester 1\Graduation research\Research logs\Q6" | H36: springer_q6.bib
A37: arXiv.org | B37: Q6 | C37: =_xlfn.XLOOKUP("Q6",queries!A7, queries!D7) -> ("Spiking neural network*" OR "SNN" OR "neuromorphic network*" OR "deep spiking network*" OR "pulsed neural network*" OR "event-driven neural network" OR "event-based spiking network") AND ("Hybrid ANN-SNN" OR "ANN-SNN conversion" OR "hybrid neural network*" OR "hybrid spiking network*" OR "artificial and spiking neural network*") AND ("software simulation" OR "neuromorphic hardware" OR "Loihi" OR "SpiNNaker" OR "TrueNorth" OR "BindsNET" OR "snnTorch" OR "neuromorphic simulator") | D37: 9 | E37: 45967 | F37: Queried the Abstract field only; (2015-2025) | G37: "D:\MyMasterDegreeJourney\Second year\Semester 1\Graduation research\Research logs\Q6" | H37: arxiv_q6.bib
A38: IEEE Xplore | B38: Q7 | C38: =_xlfn.XLOOKUP("Q7",queries!A8, queries!D8) -> ("Spiking neural network*" OR "SNN" OR "neuromorphic network*" OR "deep spiking network*" OR "pulsed neural network*" OR "event-driven neural network" OR "event-based spiking network") AND ( "Learnable encoding" OR "Adaptive encoding" OR "learnable spike encoding" OR "adaptive spike encoding" OR "trainable encoder" OR "differentiable encoding" OR "plastic encoding" OR "adaptive threshold encoding" OR "learnable threshold" OR "surrogate gradient") | D38: 7 | E38: 45980 | F38: search All ; Filters Applied: open access only+ Articles 01/01/2015 - 11/19/2025 | G38: "D:\MyMasterDegreeJourney\Second year\Semester 1\Graduation research\Research logs\Q7" | H38: ieee_q7.bib
A39: ACM Digital Library | B39: Q7 | C39: =_xlfn.XLOOKUP("Q7",queries!A8, queries!D8) -> ("Spiking neural network*" OR "SNN" OR "neuromorphic network*" OR "deep spiking network*" OR "pulsed neural network*" OR "event-driven neural network" OR "event-based spiking network") AND ( "Learnable encoding" OR "Adaptive encoding" OR "learnable spike encoding" OR "adaptive spike encoding" OR "trainable encoder" OR "differentiable encoding" OR "plastic encoding" OR "adaptive threshold encoding" OR "learnable threshold" OR "surrogate gradient") | D39: 6 | E39: 45980 | F39: (1) All fields – spiking or neuromorphic neural network terms, (2) Abstract – learnable/adaptive encoding terms. 01/01/2015 - 11/19/2025 | G39: "D:\MyMasterDegreeJourney\Second year\Semester 1\Graduation research\Research logs\Q7"
A40: Scopus | B40: Q7 | C40: ( TITLE-ABS-KEY ( "Spiking neural network*" OR SNN OR "neuromorphic network*" OR "deep spiking network*" OR "pulsed neural network*" OR "event-driven neural network" OR "event-based spiking network" ) ) AND ( ABS ( "Learnable encoding" OR "Adaptive encoding" OR "learnable spike encoding" OR "adaptive spike encoding" OR "trainable encoder" OR "differentiable encoding" OR "plastic encoding" OR "adaptive threshold encoding" OR "learnable threshold" ) ) AND PUBYEAR > 2014 AND PUBYEAR < 2026 AND ( LIMIT-TO ( OA , "all" ) ) AND ( LIMIT-TO ( LANGUAGE , "English" ) ) | D40: 3 | E40: 45980 | F40: (1) TITLE-ABS-KEY – spiking or neuromorphic neural network terms, (2) Abstract – learnable/adaptive encoding terms. 2015 - 2026 , English | G40: "D:\MyMasterDegreeJourney\Second year\Semester 1\Graduation research\Research logs\Q7"
...

Sheet inclusion criteria
A1: No. | B1: Inclusion Criterion | C1: Rationale (why)
A2: i1 | B2: Publication Type: Peer-reviewed journal/conference papers; arXiv preprintst. | C2: This ensures scientific rigor by including only peer-reviewed publications, as well as arXiv preprints that are subjected to manual quality assessment during the review process.
A3: i2 | B3: Language: English | C3: English-language restriction guarantees consistency in interpretation and quality assessment while avoiding translation bias. Nearly all core SNN research is published in English.
A4: i3 | B4: Domain: Studies on SNNs or hybrid ANN--SNN systems. | C4: Ensures inclusion of studies that explicitly integrate both artificial and spiking neural elements, highlighting approaches where ANN and SNN parts interact functionally (rather than being compared separately). This captures the core objective of investigating hybridized, cooperative learning frameworks.
A5: i4 | B5: Focus: Proposes, compares, or evaluates learnable/adaptive spike-encoding methods. | C5: Targets studies contributing novel or comparative insights into adaptive encoding strategies, aligning directly with the main research questions on learnability and adaptation.
A6: i5 | B6: Accessibility: Studies that are fully accessible to the public, with complete full-text available online without subscription or institutional login (i.e., openly accessible to any reader). | C6: Ensures transparency, verifiability, and reproducibility of findings by restricting inclusion to open-access literature that can be independently examined.
A7: i6 | B7: Time Range: 2015-2025 | C7: Limits the corpus to a relevant modern decade of SNN research, capturing advances in hybrid ANN–SNN integration and learnable encoding emerging after major deep-learning breakthroughs.

Sheet exclusion criteria
A1: No. | B1: Exclusion Criterion | C1: Rationale (why)
A2: e1 | B2: Publication Type: Books, theses, editorials, non-peer-reviewed workshop papers. | C2: Excludes materials lacking formal peer review or research validation to ensure only rigorously evaluated scientific contributions are considered.
A3: e2 | B3: Language: Non-English publications. | C3: Eliminates translation bias and ensures consistent interpretation and quality assessment, since most primary SNN studies are published in English.
A4: e3 | B4: Domain: Works unrelated to spiking neural networks, hybrid ANN–SNN systems, or spike-based processing. | C4: Focuses solely on a pure SNN or ANN without any integration, or cooperation between spiking and non-spiking components.
A5: e4 | B5: Focus: Studies using only fixed, rule-based encoding without learnable components, or papers focused solely on hardware implementation without discussing spike-encoding methods. | C5: Excludes works that use fixed or rule-based encoding with no learnable or adaptive mechanism, or that focus solely on hardware or implementation aspects without addressing spike-encoding methods.
A6: e5 | B6: Accessibility: Publications behind paywalls, requiring institutional or paid access, or providing only abstracts or partial previews. | C6: Guarantees transparency and reproducibility by including only fully accessible, verifiable studies that can be independently reviewed.
A7: e6 | B7: Time Range: Publications prior to 2015. | C7: Restricts the scope to the modern era of deep learning–driven SNN and hybrid ANN–SNN research, ensuring the inclusion of up-to-date and methodologically relevant studies.

Sheet QA rubrics
A1: Criterion Group | B1: Assessment Question | C1: Scoring Guide | D1: Where to Look
A2: QA1. Purpose & Context | B2: Are the study’s aim and research context (domain, data, environment) clearly described? | C2: 0 = Unclear 1 = Partially clear 2 = Clearly stated & contextualized | D2: Abstract, Introduction, Problem Statement
A3: QA2. Methodological Quality | B3: Is the study design or methodology appropriate and well explained? | C3: 0 = Unclear 1 = Mentioned 2 = Clearly described & justified | D3: Methods, Model Architecture, Preprocessing
A4: QA3. Data & Tools Transparency | B4: Are datasets, tools, or code identified and accessible? | C4: 0 = None 1 = Mentioned only 2 = Publicly available / detailed | D4: Dataset section, Implementation details, GitHub
A5: QA4. Rigor & Validity | B5: Are threats to validity or methodological limitations acknowledged or mitigated? | C5: 0 = Absent 1 = Briefly mentioned 2 = Systematically addressed | D5: Discussion, Threats to Validity, Ablation
A6: QA5. Results & Interpretation | B6: Are results reported clearly and interpreted in light of prior work or limitations? | C6: 0 = Weak 1 = Basic 2 = Comprehensive & critical | D6: Results, Experiments, Tables/Figures
A7: QA6. Contribution & Credibility | B7: Is the contribution novel, useful, and published in a credible venue? | C7: 0 = Low 1 = Moderate 2 = High / peer-reviewed source | D7: Introduction (Contributions), Abstract, Conclusion
A10: Total Possible Score: 12
A11: Interpretation: | B11: 0–4 = Low quality (consider exclusion)
B12: 5–8 = Moderate quality (include with caution)
B13: 9–12 = High quality (strong evidence base)

Sheet data extraction & scores
A1: Rayyan_key | B1: My_Key | C1: Year | D1: Title | E1: Abstract | F1: Author | G1: Publication Title | H1: DOI | I1: Url | J1: RQ1a_Encoding_Type | K1: RQ1b_Learnable_encoding_parameters | L1: RQ1c_Training_mechanism | M1: RQ1d_Hybrid_Integration_Type | N1: RQ2a_spike_wise_efficiency | O1: RQ2b_Resource_efficiency | P1: RQ2c_Training_Behavior | Q1: RQ2d_Model_Behavior | R1: RQ3a_Dataset_modality | S1: RQ3b_Input_Representation | T1: RQ3c_Datasets_Used | U1: RQ3d_Task_or_Domain | V1: RQ3e_Evaluation_Metrics | W1: RQ4a_Limitation_Category | X1: RQ4b_Reported_Limitations | Y1: RQ4c_Research_Gaps | Z1: hardware_or_simulator | AA1: paper_type | AB1: Architecture_Type | AC1: code_availability | AD1: training_config_short | AE1: QA1. Purpose & Context | AF1: QA2. Methodological Quality | AG1: QA3. Data & Tools Transparency | AH1: QA4. Rigor & Validity | AI1: QA5. Results & Interpretation | AJ1: QA6. Contribution & Credibility | AK1: Total QA Score
